<?xml version="1.0" encoding="utf-8"?>
<!-- This URDF was automatically created by SolidWorks to URDF Exporter! Originally created by Stephen Brawner (brawner@gmail.com) 
     Commit Version: 1.6.0-4-g7f85cfe  Build Version: 1.6.7995.38578
     For more information, please see http://wiki.ros.org/sw_urdf_exporter -->
<robot
  name="alicia_duo_with_gripper">
  <mujoco>
    <compiler meshdir="../meshes" discardvisual="false" />
    <contact>
      <exclude body1="base_link" body2="Link1"/>
      <exclude body1="Link1" body2="Link2"/>
      <exclude body1="Link2" body2="Link3"/>
      <exclude body1="Link3" body2="Link4"/>
      <exclude body1="Link4" body2="Link5"/>
      <exclude body1="Link5" body2="Link6"/>
      <exclude body1="Link6" body2="Link7"/>
      <exclude body1="Link6" body2="Link8"/>
    </contact>
  </mujoco>
  <link
    name="base_link">
    <inertial>
      <origin
        xyz="0.000826234790037244 0.00797844273246936 0.0457675129432197"
        rpy="0 0 0" />
      <mass
        value="0.733961424639881" />
      <inertia
        ixx="0.00138410344771636"
        ixy="5.6720111040394E-05"
        ixz="5.14360164234926E-07"
        iyy="0.00173617223701436"
        iyz="-1.48652204589359E-05"
        izz="0.00274667683203449" />
    </inertial>
    <visual>
      <origin
        xyz="0 0 0"
        rpy="0 0 0" />
      <geometry>
        <mesh
          filename="package://lingdong_URDF_3.0/meshes/base_link.STL" />
      </geometry>
      <material
        name="">
        <color
          rgba="0.807843137254902 0.843137254901961 0.905882352941176 1" />
      </material>
    </visual>
    <collision>
      <origin
        xyz="0 0 0"
        rpy="0 0 0" />
      <geometry>
        <mesh
          filename="package://lingdong_URDF_3.0/meshes/base_link.STL" />
      </geometry>
    </collision>
  </link>
  <link
    name="Link1">
    <inertial>
      <origin
        xyz="-0.00023059596979322 -1.29044880289368E-05 0.00303135656120138"
        rpy="0 0 0" />
      <mass
        value="0.195233452997315" />
      <inertia
        ixx="0.000258351125070495"
        ixy="8.79363230470574E-07"
        ixz="-6.87511809706063E-07"
        iyy="0.000149307709386745"
        iyz="-1.0770311123737E-06"
        izz="0.00033979127403906" />
    </inertial>
    <visual>
      <origin
        xyz="0 0 0"
        rpy="0 0 0" />
      <geometry>
        <mesh
          filename="package://lingdong_URDF_3.0/meshes/Link1.STL" />
      </geometry>
      <material
        name="">
        <color
          rgba="0.796078431372549 0.823529411764706 0.937254901960784 1" />
      </material>
    </visual>
    <collision>
      <origin
        xyz="0 0 0"
        rpy="0 0 0" />
      <geometry>
        <mesh
          filename="package://lingdong_URDF_3.0/meshes/Link1.STL" />
      </geometry>
    </collision>
  </link>
  <joint
    name="Joint1"
    type="revolute">
    <origin
      xyz="0 0 0.1295"
      rpy="0 0 0" />
    <parent
      link="base_link" />
    <child
      link="Link1" />
    <axis
      xyz="0 0 -1" />
    <limit
      lower="-2.7925"
      upper="2.7525"
      effort="5"
      velocity="12" />
  </joint>
  <link
    name="Link2">
    <inertial>
      <origin
        xyz="0.150588695622621 0.000942409990636529 0.000567598737005918"
        rpy="0 0 0" />
      <mass
        value="0.207033693061785" />
      <inertia
        ixx="0.000128135500181764"
        ixy="1.19125955596779E-07"
        ixz="1.66696805664368E-06"
        iyy="0.00020570839060521"
        iyz="-3.50025103451337E-07"
        izz="0.000122721347332605" />
    </inertial>
    <visual>
      <origin
        xyz="0 0 0"
        rpy="0 0 0" />
      <geometry>
        <mesh
          filename="package://lingdong_URDF_3.0/meshes/Link2.STL" />
      </geometry>
      <material
        name="">
        <color
          rgba="0.807843137254902 0.843137254901961 0.905882352941176 1" />
      </material>
    </visual>
    <collision>
      <origin
        xyz="0 0 0"
        rpy="0 0 0" />
      <geometry>
        <mesh
          filename="package://lingdong_URDF_3.0/meshes/Link2.STL" />
      </geometry>
    </collision>
  </link>
  <joint
    name="Joint2"
    type="revolute">
    <origin
      xyz="0 0 0.0428699999999999"
      rpy="1.5707963267949 -1.5707963267949 0" />
    <parent
      link="Link1" />
    <child
      link="Link2" />
    <axis
      xyz="0 0 1" />
    <limit
      lower="-2.443"
      upper="2.443"
      effort="5"
      velocity="12" />
  </joint>
  <link
    name="Link3">
    <inertial>
      <origin
        xyz="-0.00248143778782728 -0.0557863224791791 -0.000269720958938662"
        rpy="0 0 0" />
      <mass
        value="0.0845575643881721" />
      <inertia
        ixx="7.61918231204228E-05"
        ixy="-2.26498109370297E-06"
        ixz="-3.82299433438499E-07"
        iyy="2.87941476377691E-05"
        iyz="-5.38445154034655E-06"
        izz="8.04370526946762E-05" />
    </inertial>
    <visual>
      <origin
        xyz="0 0 0"
        rpy="0 0 0" />
      <geometry>
        <mesh
          filename="package://lingdong_URDF_3.0/meshes/Link3.STL" />
      </geometry>
      <material
        name="">
        <color
          rgba="0.792156862745098 0.819607843137255 0.933333333333333 1" />
      </material>
    </visual>
    <collision>
      <origin
        xyz="0 0 0"
        rpy="0 0 0" />
      <geometry>
        <mesh
          filename="package://lingdong_URDF_3.0/meshes/Link3.STL" />
      </geometry>
    </collision>
  </link>
  <joint
    name="Joint3"
    type="revolute">
    <origin
      xyz="0.223671302741224 0.0225916129580062 -5.00000000004269E-05"
      rpy="0 0 -2.35619455367747" />
    <parent
      link="Link2" />
    <child
      link="Link3" />
    <axis
      xyz="0 0 1" />
    <limit
      lower="-2.06"
      upper="2.06"
      effort="5"
      velocity="12" />
  </joint>
  <link
    name="Link4">
    <inertial>
      <origin
        xyz="-0.000298365504307174 -0.000601369741452302 -0.0659740416550564"
        rpy="0 0 0" />
      <mass
        value="0.0653695985152062" />
      <inertia
        ixx="7.03004189278632E-05"
        ixy="9.68417874269635E-09"
        ixz="-7.50131698707186E-07"
        iyy="6.87470299051185E-05"
        iyz="-4.45271859245362E-08"
        izz="1.68226189343447E-05" />
    </inertial>
    <visual>
      <origin
        xyz="0 0 0"
        rpy="0 0 0" />
      <geometry>
        <mesh
          filename="package://lingdong_URDF_3.0/meshes/Link4.STL" />
      </geometry>
      <material
        name="">
        <color
          rgba="0.792156862745098 0.819607843137255 0.933333333333333 1" />
      </material>
    </visual>
    <collision>
      <origin
        xyz="0 0 0"
        rpy="0 0 0" />
      <geometry>
        <mesh
          filename="package://lingdong_URDF_3.0/meshes/Link4.STL" />
      </geometry>
    </collision>
  </link>
  <joint
    name="Joint4"
    type="revolute">
    <origin
      xyz="0.00211000000000205 -0.0990000000000029 -0.000199999999999935"
      rpy="1.5707963267949 0 -3.14159265358979" />
    <parent
      link="Link3" />
    <child
      link="Link4" />
    <axis
      xyz="0 0 -1" />
    <limit
      lower="-2.7925"
      upper="2.7925"
      effort="5"
      velocity="12" />
  </joint>
  <link
    name="Link5">
    <inertial>
      <origin
        xyz="-0.011368423379793 -0.0308687469846974 0.000870449933411358"
        rpy="0 0 0" />
      <mass
        value="0.0507639016939595" />
      <inertia
        ixx="1.8770101707632E-05"
        ixy="-2.01098609907273E-06"
        ixz="5.15226500412765E-08"
        iyy="2.51021034466019E-05"
        iyz="-4.22412451734295E-08"
        izz="1.72571710040497E-05" />
    </inertial>
    <visual>
      <origin
        xyz="0 0 0"
        rpy="0 0 0" />
      <geometry>
        <mesh
          filename="package://lingdong_URDF_3.0/meshes/Link5.STL" />
      </geometry>
      <material
        name="">
        <color
          rgba="0.792156862745098 0.819607843137255 0.933333333333333 1" />
      </material>
    </visual>
    <collision>
      <origin
        xyz="0 0 0"
        rpy="0 0 0" />
      <geometry>
        <mesh
          filename="package://lingdong_URDF_3.0/meshes/Link5.STL" />
      </geometry>
    </collision>
  </link>
  <joint
    name="Joint5"
    type="revolute">
    <origin
      xyz="0 -0.000500000000000358 -0.12235"
      rpy="1.5707963267949 0 3.14159265358979" />
    <parent
      link="Link4" />
    <child
      link="Link5" />
    <axis
      xyz="0 0 1" />
    <limit
      lower="-2.095"
      upper="2.095"
      effort="5"
      velocity="12" />
  </joint>
  <link
    name="Link6">
    <inertial>
      <origin
        xyz="-0.0284286209063363 -0.000164331776074633 0.0356458378036801"
        rpy="0 0 0" />
      <mass
        value="0.123298967748658" />
      <inertia
        ixx="8.15187871372542E-05"
        ixy="1.00502626885531E-08"
        ixz="-3.58286144151258E-06"
        iyy="3.34532452274712E-05"
        iyz="2.08982135984205E-08"
        izz="8.71601554199556E-05" />
    </inertial>
    <visual>
      <origin
        xyz="0 0 0"
        rpy="0 0 0" />
      <geometry>
        <mesh
          filename="package://lingdong_URDF_3.0/meshes/Link6.STL" />
      </geometry>
      <material
        name="">
        <color
          rgba="0.592156862745098 0.666666666666667 0.682352941176471 1" />
      </material>
    </visual>
    <collision>
      <origin
        xyz="0 0 0"
        rpy="0 0 0" />
      <geometry>
        <mesh
          filename="package://lingdong_URDF_3.0/meshes/Link6.STL" />
      </geometry>
    </collision>
  </link>
  <joint
    name="Joint6"
    type="revolute">
    <origin
      xyz="-0.00384999999999946 -0.0574999999999999 0.00100000000000069"
      rpy="1.5707963267949 0 0" />
    <parent
      link="Link5" />
    <child
      link="Link6" />
    <axis
      xyz="0 0 -1" />
    <limit
      lower="-3.14"
      upper="3.14"
      effort="5"
      velocity="12" />
  </joint>
  <link
    name="Link7">
    <inertial>
      <origin
        xyz="-2.97087515144234E-08 -0.0434087591943531 0.0106596716155943"
        rpy="0 0 0" />
      <mass
        value="0.0256461121677846" />
      <inertia
        ixx="6.46830326573711E-06"
        ixy="2.3954380101872E-11"
        ixz="4.63721305371709E-12"
        iyy="5.13428741941763E-06"
        iyz="1.26432048814165E-06"
        izz="8.03606347912525E-06" />
    </inertial>
    <visual>
      <origin
        xyz="0 0 0"
        rpy="0 0 0" />
      <geometry>
        <mesh
          filename="package://lingdong_URDF_3.0/meshes/Link7.STL" />
      </geometry>
      <material
        name="">
        <color
          rgba="0.807843137254902 0.843137254901961 0.905882352941176 1" />
      </material>
    </visual>
    <collision>
      <origin
        xyz="0 0 0"
        rpy="0 0 0" />
      <geometry>
        <mesh
          filename="package://lingdong_URDF_3.0/meshes/Link7.STL" />
      </geometry>
    </collision>
  </link>
  <joint
    name="left_finger"
    type="prismatic">
    <origin
      xyz="-0.0002 -0.036537 0.13098"
      rpy="1.5708 0 0" />
    <parent
      link="Link6" />
    <child
      link="Link7" />
    <axis
      xyz="0 0 -1" />
    <limit
      lower="0"
      upper="-0.05"
      effort="5"
      velocity="12" />
  </joint>
  <link
    name="Link8">
    <inertial>
      <origin
        xyz="2.97087526801576E-08 0.0434087591943507 0.0106596716155943"
        rpy="0 0 0" />
      <mass
        value="0.0256461121677874" />
      <inertia
        ixx="6.46830326573821E-06"
        ixy="2.3954379825951E-11"
        ixz="-4.63721285095794E-12"
        iyy="5.13428741941822E-06"
        iyz="-1.2643204881421E-06"
        izz="8.03606347912601E-06" />
    </inertial>
    <visual>
      <origin
        xyz="0 0 0"
        rpy="0 0 0" />
      <geometry>
        <mesh
          filename="package://lingdong_URDF_3.0/meshes/Link8.STL" />
      </geometry>
      <material
        name="">
        <color
          rgba="0.807843137254902 0.843137254901961 0.905882352941176 1" />
      </material>
    </visual>
    <collision>
      <origin
        xyz="0 0 0"
        rpy="0 0 0" />
      <geometry>
        <mesh
          filename="package://lingdong_URDF_3.0/meshes/Link8.STL" />
      </geometry>
    </collision>
  </link>
  <joint
    name="right_finger"
    type="prismatic">
    <origin
      xyz="-0.0002 0.036518 0.13098"
      rpy="-1.5708 0 0" />
    <parent
      link="Link6" />
    <child
      link="Link8" />
    <axis
      xyz="0 0 1" />
    <limit
      lower="0.05"
      upper="0"
      effort="5"
      velocity="12" />
  </joint>
</robot>